[2022-02-01 06:35:21,862] {taskinstance.py:1032} INFO - Dependencies all met for <TaskInstance: LocalIngestionDag.ingest manual__2022-02-01T06:34:32.206809+00:00 [queued]>
[2022-02-01 06:35:24,635] {taskinstance.py:1032} INFO - Dependencies all met for <TaskInstance: LocalIngestionDag.ingest manual__2022-02-01T06:34:32.206809+00:00 [queued]>
[2022-02-01 06:35:24,662] {taskinstance.py:1238} INFO - 
--------------------------------------------------------------------------------
[2022-02-01 06:35:24,688] {taskinstance.py:1239} INFO - Starting attempt 1 of 1
[2022-02-01 06:35:24,691] {taskinstance.py:1240} INFO - 
--------------------------------------------------------------------------------
[2022-02-01 06:35:27,007] {taskinstance.py:1259} INFO - Executing <Task(BashOperator): ingest> on 2022-02-01 06:34:32.206809+00:00
[2022-02-01 06:35:27,442] {standard_task_runner.py:52} INFO - Started process 377 to run task
[2022-02-01 06:35:27,520] {standard_task_runner.py:76} INFO - Running: ['***', 'tasks', 'run', 'LocalIngestionDag', 'ingest', 'manual__2022-02-01T06:34:32.206809+00:00', '--job-id', '16', '--raw', '--subdir', 'DAGS_FOLDER/local.py', '--cfg-path', '/tmp/tmp5ngzsf4w', '--error-file', '/tmp/tmp9dw70acq']
[2022-02-01 06:35:27,636] {standard_task_runner.py:77} INFO - Job 16: Subtask ingest
[2022-02-01 06:35:32,434] {logging_mixin.py:109} INFO - Running <TaskInstance: LocalIngestionDag.ingest manual__2022-02-01T06:34:32.206809+00:00 [running]> on host beeadfc87c61
[2022-02-01 06:35:38,583] {taskinstance.py:1426} INFO - Exporting the following env vars:
AIRFLOW_CTX_DAG_OWNER=***
AIRFLOW_CTX_DAG_ID=LocalIngestionDag
AIRFLOW_CTX_TASK_ID=ingest
AIRFLOW_CTX_EXECUTION_DATE=2022-02-01T06:34:32.206809+00:00
AIRFLOW_CTX_DAG_RUN_ID=manual__2022-02-01T06:34:32.206809+00:00
[2022-02-01 06:35:38,595] {subprocess.py:62} INFO - Tmp dir root location: 
 /tmp
[2022-02-01 06:35:38,605] {subprocess.py:74} INFO - Running command: ['bash', '-c', 'pwd"']
[2022-02-01 06:35:39,507] {subprocess.py:85} INFO - Output:
[2022-02-01 06:35:39,817] {subprocess.py:89} INFO - bash: -c: line 0: unexpected EOF while looking for matching `"'
[2022-02-01 06:35:39,824] {subprocess.py:89} INFO - bash: -c: line 1: syntax error: unexpected end of file
[2022-02-01 06:35:39,832] {subprocess.py:93} INFO - Command exited with return code 1
[2022-02-01 06:35:40,398] {taskinstance.py:1700} ERROR - Task failed with exception
Traceback (most recent call last):
  File "/home/airflow/.local/lib/python3.7/site-packages/airflow/models/taskinstance.py", line 1329, in _run_raw_task
    self._execute_task_with_callbacks(context)
  File "/home/airflow/.local/lib/python3.7/site-packages/airflow/models/taskinstance.py", line 1455, in _execute_task_with_callbacks
    result = self._execute_task(context, self.task)
  File "/home/airflow/.local/lib/python3.7/site-packages/airflow/models/taskinstance.py", line 1511, in _execute_task
    result = execute_callable(context=context)
  File "/home/airflow/.local/lib/python3.7/site-packages/airflow/operators/bash.py", line 188, in execute
    f'Bash command failed. The command returned a non-zero exit code {result.exit_code}.'
airflow.exceptions.AirflowException: Bash command failed. The command returned a non-zero exit code 1.
[2022-02-01 06:35:41,208] {taskinstance.py:1277} INFO - Marking task as FAILED. dag_id=LocalIngestionDag, task_id=ingest, execution_date=20220201T063432, start_date=20220201T063522, end_date=20220201T063541
[2022-02-01 06:35:43,454] {standard_task_runner.py:92} ERROR - Failed to execute job 16 for task ingest
Traceback (most recent call last):
  File "/home/airflow/.local/lib/python3.7/site-packages/airflow/task/task_runner/standard_task_runner.py", line 85, in _start_by_fork
    args.func(args, dag=self.dag)
  File "/home/airflow/.local/lib/python3.7/site-packages/airflow/cli/cli_parser.py", line 48, in command
    return func(*args, **kwargs)
  File "/home/airflow/.local/lib/python3.7/site-packages/airflow/utils/cli.py", line 92, in wrapper
    return f(*args, **kwargs)
  File "/home/airflow/.local/lib/python3.7/site-packages/airflow/cli/commands/task_command.py", line 298, in task_run
    _run_task_by_selected_method(args, dag, ti)
  File "/home/airflow/.local/lib/python3.7/site-packages/airflow/cli/commands/task_command.py", line 107, in _run_task_by_selected_method
    _run_raw_task(args, ti)
  File "/home/airflow/.local/lib/python3.7/site-packages/airflow/cli/commands/task_command.py", line 184, in _run_raw_task
    error_file=args.error_file,
  File "/home/airflow/.local/lib/python3.7/site-packages/airflow/utils/session.py", line 70, in wrapper
    return func(*args, session=session, **kwargs)
  File "/home/airflow/.local/lib/python3.7/site-packages/airflow/models/taskinstance.py", line 1329, in _run_raw_task
    self._execute_task_with_callbacks(context)
  File "/home/airflow/.local/lib/python3.7/site-packages/airflow/models/taskinstance.py", line 1455, in _execute_task_with_callbacks
    result = self._execute_task(context, self.task)
  File "/home/airflow/.local/lib/python3.7/site-packages/airflow/models/taskinstance.py", line 1511, in _execute_task
    result = execute_callable(context=context)
  File "/home/airflow/.local/lib/python3.7/site-packages/airflow/operators/bash.py", line 188, in execute
    f'Bash command failed. The command returned a non-zero exit code {result.exit_code}.'
airflow.exceptions.AirflowException: Bash command failed. The command returned a non-zero exit code 1.
[2022-02-01 06:35:45,518] {local_task_job.py:154} INFO - Task exited with return code 1
[2022-02-01 06:35:46,636] {local_task_job.py:264} INFO - 0 downstream tasks scheduled from follow-on schedule check
