[2022-02-01 06:37:04,761] {taskinstance.py:1032} INFO - Dependencies all met for <TaskInstance: LocalIngestionDag.ingest scheduled__2021-10-02T06:00:00+00:00 [queued]>
[2022-02-01 06:37:06,796] {taskinstance.py:1032} INFO - Dependencies all met for <TaskInstance: LocalIngestionDag.ingest scheduled__2021-10-02T06:00:00+00:00 [queued]>
[2022-02-01 06:37:06,798] {taskinstance.py:1238} INFO - 
--------------------------------------------------------------------------------
[2022-02-01 06:37:06,805] {taskinstance.py:1239} INFO - Starting attempt 1 of 1
[2022-02-01 06:37:06,807] {taskinstance.py:1240} INFO - 
--------------------------------------------------------------------------------
[2022-02-01 06:37:07,627] {taskinstance.py:1259} INFO - Executing <Task(BashOperator): ingest> on 2021-10-02 06:00:00+00:00
[2022-02-01 06:37:08,604] {standard_task_runner.py:52} INFO - Started process 458 to run task
[2022-02-01 06:37:09,832] {standard_task_runner.py:76} INFO - Running: ['***', 'tasks', 'run', 'LocalIngestionDag', 'ingest', 'scheduled__2021-10-02T06:00:00+00:00', '--job-id', '29', '--raw', '--subdir', 'DAGS_FOLDER/local.py', '--cfg-path', '/tmp/tmp9rh3ni6j', '--error-file', '/tmp/tmpjk_rfpyr']
[2022-02-01 06:37:09,964] {standard_task_runner.py:77} INFO - Job 29: Subtask ingest
[2022-02-01 06:37:12,826] {logging_mixin.py:109} INFO - Running <TaskInstance: LocalIngestionDag.ingest scheduled__2021-10-02T06:00:00+00:00 [running]> on host beeadfc87c61
[2022-02-01 06:37:20,916] {taskinstance.py:1426} INFO - Exporting the following env vars:
AIRFLOW_CTX_DAG_OWNER=***
AIRFLOW_CTX_DAG_ID=LocalIngestionDag
AIRFLOW_CTX_TASK_ID=ingest
AIRFLOW_CTX_EXECUTION_DATE=2021-10-02T06:00:00+00:00
AIRFLOW_CTX_DAG_RUN_ID=scheduled__2021-10-02T06:00:00+00:00
[2022-02-01 06:37:21,002] {subprocess.py:62} INFO - Tmp dir root location: 
 /tmp
[2022-02-01 06:37:21,020] {subprocess.py:74} INFO - Running command: ['bash', '-c', 'pwd"']
[2022-02-01 06:37:22,193] {subprocess.py:85} INFO - Output:
[2022-02-01 06:37:22,342] {subprocess.py:89} INFO - bash: -c: line 0: unexpected EOF while looking for matching `"'
[2022-02-01 06:37:22,350] {subprocess.py:89} INFO - bash: -c: line 1: syntax error: unexpected end of file
[2022-02-01 06:37:22,388] {subprocess.py:93} INFO - Command exited with return code 1
[2022-02-01 06:37:22,949] {taskinstance.py:1700} ERROR - Task failed with exception
Traceback (most recent call last):
  File "/home/airflow/.local/lib/python3.7/site-packages/airflow/models/taskinstance.py", line 1329, in _run_raw_task
    self._execute_task_with_callbacks(context)
  File "/home/airflow/.local/lib/python3.7/site-packages/airflow/models/taskinstance.py", line 1455, in _execute_task_with_callbacks
    result = self._execute_task(context, self.task)
  File "/home/airflow/.local/lib/python3.7/site-packages/airflow/models/taskinstance.py", line 1511, in _execute_task
    result = execute_callable(context=context)
  File "/home/airflow/.local/lib/python3.7/site-packages/airflow/operators/bash.py", line 188, in execute
    f'Bash command failed. The command returned a non-zero exit code {result.exit_code}.'
airflow.exceptions.AirflowException: Bash command failed. The command returned a non-zero exit code 1.
[2022-02-01 06:37:25,996] {taskinstance.py:1277} INFO - Marking task as FAILED. dag_id=LocalIngestionDag, task_id=ingest, execution_date=20211002T060000, start_date=20220201T063705, end_date=20220201T063725
[2022-02-01 06:37:26,523] {standard_task_runner.py:92} ERROR - Failed to execute job 29 for task ingest
Traceback (most recent call last):
  File "/home/airflow/.local/lib/python3.7/site-packages/airflow/task/task_runner/standard_task_runner.py", line 85, in _start_by_fork
    args.func(args, dag=self.dag)
  File "/home/airflow/.local/lib/python3.7/site-packages/airflow/cli/cli_parser.py", line 48, in command
    return func(*args, **kwargs)
  File "/home/airflow/.local/lib/python3.7/site-packages/airflow/utils/cli.py", line 92, in wrapper
    return f(*args, **kwargs)
  File "/home/airflow/.local/lib/python3.7/site-packages/airflow/cli/commands/task_command.py", line 298, in task_run
    _run_task_by_selected_method(args, dag, ti)
  File "/home/airflow/.local/lib/python3.7/site-packages/airflow/cli/commands/task_command.py", line 107, in _run_task_by_selected_method
    _run_raw_task(args, ti)
  File "/home/airflow/.local/lib/python3.7/site-packages/airflow/cli/commands/task_command.py", line 184, in _run_raw_task
    error_file=args.error_file,
  File "/home/airflow/.local/lib/python3.7/site-packages/airflow/utils/session.py", line 70, in wrapper
    return func(*args, session=session, **kwargs)
  File "/home/airflow/.local/lib/python3.7/site-packages/airflow/models/taskinstance.py", line 1329, in _run_raw_task
    self._execute_task_with_callbacks(context)
  File "/home/airflow/.local/lib/python3.7/site-packages/airflow/models/taskinstance.py", line 1455, in _execute_task_with_callbacks
    result = self._execute_task(context, self.task)
  File "/home/airflow/.local/lib/python3.7/site-packages/airflow/models/taskinstance.py", line 1511, in _execute_task
    result = execute_callable(context=context)
  File "/home/airflow/.local/lib/python3.7/site-packages/airflow/operators/bash.py", line 188, in execute
    f'Bash command failed. The command returned a non-zero exit code {result.exit_code}.'
airflow.exceptions.AirflowException: Bash command failed. The command returned a non-zero exit code 1.
[2022-02-01 06:37:26,674] {local_task_job.py:212} WARNING - State of this instance has been externally set to failed. Terminating instance.
[2022-02-01 06:37:27,122] {process_utils.py:124} INFO - Sending Signals.SIGTERM to group 458. PIDs of all processes in the group: [458]
[2022-02-01 06:37:27,680] {process_utils.py:75} INFO - Sending the signal Signals.SIGTERM to group 458
[2022-02-01 06:37:28,873] {process_utils.py:70} INFO - Process psutil.Process(pid=458, status='terminated', exitcode=1, started='06:37:07') (458) terminated with exit code 1
