[2022-02-01 06:35:57,277] {taskinstance.py:1032} INFO - Dependencies all met for <TaskInstance: LocalIngestionDag.ingest scheduled__2021-03-02T06:00:00+00:00 [queued]>
[2022-02-01 06:35:58,733] {taskinstance.py:1032} INFO - Dependencies all met for <TaskInstance: LocalIngestionDag.ingest scheduled__2021-03-02T06:00:00+00:00 [queued]>
[2022-02-01 06:35:58,789] {taskinstance.py:1238} INFO - 
--------------------------------------------------------------------------------
[2022-02-01 06:35:58,828] {taskinstance.py:1239} INFO - Starting attempt 1 of 1
[2022-02-01 06:35:58,841] {taskinstance.py:1240} INFO - 
--------------------------------------------------------------------------------
[2022-02-01 06:36:00,877] {taskinstance.py:1259} INFO - Executing <Task(BashOperator): ingest> on 2021-03-02 06:00:00+00:00
[2022-02-01 06:36:01,271] {standard_task_runner.py:76} INFO - Running: ['***', 'tasks', 'run', 'LocalIngestionDag', 'ingest', 'scheduled__2021-03-02T06:00:00+00:00', '--job-id', '23', '--raw', '--subdir', 'DAGS_FOLDER/local.py', '--cfg-path', '/tmp/tmporpzdgu0', '--error-file', '/tmp/tmpdfery0lf']
[2022-02-01 06:36:01,334] {standard_task_runner.py:77} INFO - Job 23: Subtask ingest
[2022-02-01 06:36:01,262] {standard_task_runner.py:52} INFO - Started process 414 to run task
[2022-02-01 06:36:16,954] {logging_mixin.py:109} INFO - Running <TaskInstance: LocalIngestionDag.ingest scheduled__2021-03-02T06:00:00+00:00 [running]> on host beeadfc87c61
[2022-02-01 06:36:27,932] {taskinstance.py:1426} INFO - Exporting the following env vars:
AIRFLOW_CTX_DAG_OWNER=***
AIRFLOW_CTX_DAG_ID=LocalIngestionDag
AIRFLOW_CTX_TASK_ID=ingest
AIRFLOW_CTX_EXECUTION_DATE=2021-03-02T06:00:00+00:00
AIRFLOW_CTX_DAG_RUN_ID=scheduled__2021-03-02T06:00:00+00:00
[2022-02-01 06:36:28,021] {subprocess.py:62} INFO - Tmp dir root location: 
 /tmp
[2022-02-01 06:36:28,059] {subprocess.py:74} INFO - Running command: ['bash', '-c', 'pwd"']
[2022-02-01 06:36:28,963] {subprocess.py:85} INFO - Output:
[2022-02-01 06:36:29,096] {subprocess.py:89} INFO - bash: -c: line 0: unexpected EOF while looking for matching `"'
[2022-02-01 06:36:29,100] {subprocess.py:89} INFO - bash: -c: line 1: syntax error: unexpected end of file
[2022-02-01 06:36:29,135] {subprocess.py:93} INFO - Command exited with return code 1
[2022-02-01 06:36:30,475] {taskinstance.py:1700} ERROR - Task failed with exception
Traceback (most recent call last):
  File "/home/airflow/.local/lib/python3.7/site-packages/airflow/models/taskinstance.py", line 1329, in _run_raw_task
    self._execute_task_with_callbacks(context)
  File "/home/airflow/.local/lib/python3.7/site-packages/airflow/models/taskinstance.py", line 1455, in _execute_task_with_callbacks
    result = self._execute_task(context, self.task)
  File "/home/airflow/.local/lib/python3.7/site-packages/airflow/models/taskinstance.py", line 1511, in _execute_task
    result = execute_callable(context=context)
  File "/home/airflow/.local/lib/python3.7/site-packages/airflow/operators/bash.py", line 188, in execute
    f'Bash command failed. The command returned a non-zero exit code {result.exit_code}.'
airflow.exceptions.AirflowException: Bash command failed. The command returned a non-zero exit code 1.
[2022-02-01 06:36:33,332] {taskinstance.py:1277} INFO - Marking task as FAILED. dag_id=LocalIngestionDag, task_id=ingest, execution_date=20210302T060000, start_date=20220201T063557, end_date=20220201T063632
[2022-02-01 06:36:41,492] {standard_task_runner.py:92} ERROR - Failed to execute job 23 for task ingest
Traceback (most recent call last):
  File "/home/airflow/.local/lib/python3.7/site-packages/airflow/task/task_runner/standard_task_runner.py", line 85, in _start_by_fork
    args.func(args, dag=self.dag)
  File "/home/airflow/.local/lib/python3.7/site-packages/airflow/cli/cli_parser.py", line 48, in command
    return func(*args, **kwargs)
  File "/home/airflow/.local/lib/python3.7/site-packages/airflow/utils/cli.py", line 92, in wrapper
    return f(*args, **kwargs)
  File "/home/airflow/.local/lib/python3.7/site-packages/airflow/cli/commands/task_command.py", line 298, in task_run
    _run_task_by_selected_method(args, dag, ti)
  File "/home/airflow/.local/lib/python3.7/site-packages/airflow/cli/commands/task_command.py", line 107, in _run_task_by_selected_method
    _run_raw_task(args, ti)
  File "/home/airflow/.local/lib/python3.7/site-packages/airflow/cli/commands/task_command.py", line 184, in _run_raw_task
    error_file=args.error_file,
  File "/home/airflow/.local/lib/python3.7/site-packages/airflow/utils/session.py", line 70, in wrapper
    return func(*args, session=session, **kwargs)
  File "/home/airflow/.local/lib/python3.7/site-packages/airflow/models/taskinstance.py", line 1329, in _run_raw_task
    self._execute_task_with_callbacks(context)
  File "/home/airflow/.local/lib/python3.7/site-packages/airflow/models/taskinstance.py", line 1455, in _execute_task_with_callbacks
    result = self._execute_task(context, self.task)
  File "/home/airflow/.local/lib/python3.7/site-packages/airflow/models/taskinstance.py", line 1511, in _execute_task
    result = execute_callable(context=context)
  File "/home/airflow/.local/lib/python3.7/site-packages/airflow/operators/bash.py", line 188, in execute
    f'Bash command failed. The command returned a non-zero exit code {result.exit_code}.'
airflow.exceptions.AirflowException: Bash command failed. The command returned a non-zero exit code 1.
[2022-02-01 06:36:42,155] {local_task_job.py:212} WARNING - State of this instance has been externally set to failed. Terminating instance.
[2022-02-01 06:36:42,530] {process_utils.py:124} INFO - Sending Signals.SIGTERM to group 414. PIDs of all processes in the group: [414]
[2022-02-01 06:36:42,581] {process_utils.py:75} INFO - Sending the signal Signals.SIGTERM to group 414
[2022-02-01 06:36:42,628] {process_utils.py:70} INFO - Process psutil.Process(pid=414, status='terminated', exitcode=1, started='06:36:00') (414) terminated with exit code 1
